<?xml version="1.0"?>
<robot xmlns:xacro="http://www.ros.org/wiki/xacro" name="robot">

    <!-- Useful Variables (Properties) -->
    <xacro:property name="PI" value="3.14159265359" />
    <xacro:property name="effort" value="30" />
    <xacro:property name="velocity" value="10" />

    <!-- Useful Macros -->
    <xacro:macro name="default_inertial" params="mass">
        <inertial>
            <mass value="${mass}" />
            <inertia ixx="1.0" ixy="0.0" ixz="0.0"
                     iyy="1.0" iyz="0.0"
                     izz="1.0" />
        </inertial>
    </xacro:macro>
    <xacro:macro name="default_transmission" params="number">
        <transmission name="transmission_${number}">
            <type>transmission_interface/SimpleTransmission</type>
            <joint name="joint_${number}">
                <hardwareInterface>hardware_interface/PositionJointInterface</hardwareInterface>
            </joint>
            <actuator name="motor_${number}">
                <hardwareInterface>hardware_interface/PositionJointInterface</hardwareInterface>
                <mechanicalReduction>1</mechanicalReduction>
            </actuator>
        </transmission>
    </xacro:macro>


    <!-- Links -->
    
    <link name="world"/>

    <link name="base_link">
        <xacro:default_inertial mass="1"/>
        <visual>
            <origin rpy="0 0 0" xyz="-0.5 -0.5 0"/>
            <geometry>
                <mesh filename="package://robot_description/mesh/basement.STL" scale="0.01 0.01 0.01"/>
            </geometry>
        </visual>
        <collision>
            <origin rpy="0 0 0" xyz="-0.5 -0.5 0"/>
            <geometry>
                <mesh filename="package://robot_description/mesh/basement.STL" scale="0.01 0.01 0.01"/>
            </geometry>
        </collision>
    </link>

    <link name="base_plate">
        <xacro:default_inertial mass="0.1"/>
        <visual>
            <origin rpy="0 0 0" xyz="-0.39 -0.39 -0.56"/>
            <geometry>
                <mesh filename="package://robot_description/mesh/base_plate.STL" scale="0.01 0.01 0.01"/>
            </geometry>
        </visual>
        <collision>
            <origin rpy="0 0 0" xyz="-0.39 -0.39 -0.56"/>
            <geometry>
                <mesh filename="package://robot_description/mesh/base_plate.STL" scale="0.01 0.01 0.01"/>
            </geometry>
        </collision>
    </link>

    <link name="forward_drive_arm">
        <xacro:default_inertial mass="0.1"/>
        <visual>
            <origin rpy=" 0 -${PI/2} ${PI/2}" xyz="0.19 0.06 -0.08"/>
            <geometry>
                <mesh filename="package://robot_description/mesh/forward_drive_arm.STL" scale="0.01 0.01 0.01"/>
            </geometry>
        </visual>
        <collision>
            <origin rpy=" 0 -${PI/2} ${PI/2}" xyz="0.19 0.06 -0.08"/>
            <geometry>
                <mesh filename="package://robot_description/mesh/forward_drive_arm.STL" scale="0.01 0.01 0.01"/>
            </geometry>
        </collision>
    </link>

    <link name="horizontal_arm">
        <xacro:default_inertial mass="0.1"/>
        <visual>
            <origin rpy="${PI/2} 0 ${PI/2}" xyz="-0.03 -0.4 -0.06"/>
            <geometry>
                <mesh filename="package://robot_description/mesh/horizontal_arm.STL" scale="0.01 0.01 0.01"/>
            </geometry>
        </visual>
        <collision>
            <origin rpy="${PI/2} 0 ${PI/2}" xyz="-0.03 -0.4 -0.06"/>
            <geometry>
                <mesh filename="package://robot_description/mesh/horizontal_arm.STL" scale="0.01 0.01 0.01"/>
            </geometry>
        </collision>
    </link>

    <link name="claw_support">
        <xacro:default_inertial mass="0.05"/>
        <visual>
            <origin rpy="0 0 ${PI/2}" xyz="0 -0.05 -0.15"/>
            <geometry>
                <mesh filename="package://robot_description/mesh/claw_support.STL" scale="0.01 0.01 0.01"/>
            </geometry>
        </visual>
        <collision>
            <origin rpy="0 0 ${PI/2}" xyz="0 -0.05 -0.15"/>
            <geometry>
                <mesh filename="package://robot_description/mesh/claw_support.STL" scale="0.01 0.01 0.01"/>
            </geometry>
        </collision>
    </link>

    <link name="gripper_right">
        <xacro:default_inertial mass="0.01"/>
        <visual>
            <origin rpy="0 0 -${PI/2}" xyz="-0.1 0.50 -0.1"/>
            <geometry>
                <mesh filename="package://robot_description/mesh/right_finger.STL" scale="0.01 0.01 0.01"/>
            </geometry>
        </visual>
        <collision>
            <origin rpy="0 0 -${PI/2}" xyz="-0.1 0.50 -0.1"/>
            <geometry>
                <mesh filename="package://robot_description/mesh/right_finger.STL" scale="0.01 0.01 0.01"/>
            </geometry>
        </collision>
    </link>

    <link name="gripper_left">
        <xacro:default_inertial mass="0.01"/>
        <visual>
            <origin rpy="0 0 -${PI/2}" xyz="-0.04 0.50 -0.1"/>
            <geometry>
                <mesh filename="package://robot_description/mesh/left_finger.STL" scale="0.01 0.01 0.01"/>
            </geometry>
        </visual>
        <collision>
            <origin rpy="0 0 -${PI/2}" xyz="-0.04 0.50 -0.1"/>
            <geometry>
                <mesh filename="package://robot_description/mesh/left_finger.STL" scale="0.01 0.01 0.01"/>
            </geometry>
        </collision>
    </link>

    <link name="tool_link"></link>
    
    <link name='camera'>
      <static>true</static>
      <inertial>
        <mass value="0.1"/>
        <origin xyz="0.0 0 2" rpy=" ${pi/2} ${pi/2} ${pi/2}"/>
        <box_intertia m="0.1" x="0.05" y="0.05" z="0.05"/>
        <inertia
          ixx="1e-6" ixy="0" ixz="0"
          iyy="1e-6" iyz="0"
          izz="1e-6"
        />
      </inertial>

      <collision name='camera_collision'>
        <origin xyz="0 0 0" rpy=" 0 0 1.5707"/> 
        <geometry>
          <box size=".05 .05 .05"/>
        </geometry>
      </collision>

      <visual name='camera_visual'>
        <origin xyz="0 0 0" rpy=" 0 0 1.5707"/>
        <geometry>
          <box size=".05 .05 .05"/>
        </geometry>
    </visual>

  </link>
  
  <joint type="fixed" name="camera_joint">
    <static>true</static>
    <origin xyz="0 1 3" rpy="${pi/2} ${pi/2} ${pi/2}"/>
    <child link="camera"/>
    <parent link="base_link"/>
    <axis xyz="0 1 0" rpy="0 0 0"/>
  </joint>

    
    <!-- Joints -->  
    <joint name="virtual_joint" type="fixed">
        <parent link="world"/>
        <child link="base_link"/>
        <origin xyz="0 0 0" rpy="0 0 0"/>
    </joint> 

    <joint name ="joint_1" type="revolute">
        <parent link="base_link"/>
        <child link = "base_plate"/>
        <origin xyz="0 0 0.307"/>
        <axis xyz="0 0 1"/>
        <limit lower="-${PI/2}" upper="${PI/2}" effort="${effort}" velocity="${velocity}"/>
    </joint>

    <joint name ="joint_2" type="revolute">
        <parent link="base_plate"/>
        <child link = "forward_drive_arm"/>
        <origin xyz="-0.02 0 0.35"/>
        <axis xyz="1 0 0"/>
        <limit lower="-${PI/2}" upper="${PI/2}" effort="${effort}" velocity="${velocity}"/>
    </joint>

    <joint name ="joint_3" type="revolute">
        <parent link="forward_drive_arm"/>
        <child link = "horizontal_arm"/>
        <origin xyz="0 0 0.8"/>
        <axis xyz="1 0 0"/>
        <limit lower="-${PI/2}" upper="${PI/2}" effort="${effort}" velocity="${velocity}"/>
    </joint>

    <joint name ="horizontal_arm_to_claw_support" type="fixed">
        <parent link="horizontal_arm"/>
        <child link = "claw_support"/>
        <origin xyz="0 0.82 0"/>
    </joint>

    <joint name ="joint_4" type="revolute">
        <parent link="claw_support"/>
        <child link = "gripper_right"/>
        <origin xyz="-0.04 0.13 -0.1"/>
        <axis xyz="0 0 1"/>
        <limit lower="-${PI/2}" upper="0" effort="${effort}" velocity="${velocity}"/>
    </joint>

    <joint name ="joint_5" type="revolute">
        <parent link="claw_support"/>
        <child link = "gripper_left"/>
        <origin xyz="-0.22 0.13 -0.1"/>
        <axis xyz="0 0 1"/>
        <limit lower="0" upper="${PI/2}" effort="${effort}" velocity="${velocity}"/>
        <mimic joint="joint_4" multiplier="-1" offset="0"/> 
    </joint>

    <joint name ="gripper_right_to_tool" type="fixed">
        <parent link="gripper_right"/>
        <child link = "tool_link"/>
        <origin xyz="0 0 0"/>
    </joint>
    
    
    
    

    <!-- Transmissions-->
    <xacro:default_transmission number="1"/>
    <xacro:default_transmission number="2"/>
    <xacro:default_transmission number="3"/>
    <xacro:default_transmission number="4"/>


    <!-- gazebo ros_control plugin -->
    <gazebo>
        <plugin name="gazebo_ros_control" filename="libgazebo_ros_control.so">
            <robotNamespace>/robot</robotNamespace>
            <robotSimType>gazebo_ros_control/DefaultRobotHWSim</robotSimType>
            <legacyModeNS>true</legacyModeNS>
        </plugin>

        <plugin name="joint_5_mimic_joint_4" filename="libroboticsgroup_upatras_gazebo_mimic_joint_plugin.so">
          <joint>joint_4</joint>
          <mimicJoint>joint_5</mimicJoint>
          <multiplier>-1.0</multiplier>
          <offset>0</offset> 
          <maxEffort>${effort}</maxEffort>             
          <robotNamespace>/robot</robotNamespace>
        </plugin>
    </gazebo>
    
    <!-- gazebo gripper fix-->
    <gazebo>
        <plugin name="gazebo_grasp_fix" filename="libgazebo_grasp_fix.so">
        <arm>
            <arm_name>horizontal_arm</arm_name>
            <palm_link>claw_support</palm_link>
            <gripper_link>gripper_right</gripper_link>
            <gripper_link>gripper_left</gripper_link>
        </arm>
        <forces_angle_tolerance>100</forces_angle_tolerance>
        <update_rate>10</update_rate>
        <grip_count_threshold>3</grip_count_threshold>
        <max_grip_count>10</max_grip_count>
        <release_tolerance>0.001</release_tolerance>
        <disable_collisions_on_attach>true</disable_collisions_on_attach>
        <contact_topic>__default_topic__</contact_topic>
        </plugin>
    </gazebo>
  
  <!-- Camera -->
  <gazebo reference="camera">
        <material>Gazebo/Red</material>

        <sensor name="camera" type="camera">
            <pose> 0 0 0 ${pi/2} ${pi/2} ${pi/2} </pose>
            <visualize>true</visualize>
            <update_rate>10</update_rate>
            <camera>
                <horizontal_fov>1.089</horizontal_fov>
                <image>
                    <format>R8G8B8</format>
                    <width>640</width>
                    <height>480</height>
                </image>
                <clip>
                    <near>0.05</near>
                    <far>8.0</far>
                </clip>
            </camera>
            <plugin name="camera_controller" filename="libgazebo_ros_camera.so">
                <frame_name>camera_link_optical</frame_name>
            </plugin>
        </sensor>
    </gazebo>


</robot>
